Workbook

Sheet References
A1: Study ID | B1: Author | C1: Year | D1: Title | E1: Peer-Review Status | F1: Meta-Analysis
A2: a24 | B2: Agusti, C., et al. | C2: 2022 | D2: Feasibility of an online antigen self-testing strategy for SARS-CoV-2 addressed to health care and education professionals in Catalonia (Spain). The TESTA’T- COVID Project | E2: PR | F2: yes
A3: a25 | B3: Bresser, M., et al | C3: 2023 | D3: Evaluation of Covid-19 Ag-RDTs self-testing in Lesotho and Zambia | E3: PR | F3: yes
A4: a26 | B4: Chan, H.K. et al. | C4: 2024 | D4: Implementation pilot study of community self-testing for COVID-19 among employees of manufacturing industries and their household members in 2022 to 2023 | E4: PR | F4: yes
A5: a27 | B5: Chen, S.H., et al. | C5: 2023 | D5: Differential clinical characteristics and performance of home antigen tests between parents and children after household transmission of SARS-CoV-2 during the Omicron variant pandemic | E5: PR | F5: no
A6: a28 | B6: Chong, S.J. et al. | C6: 2023 | D6: Assessment of COVID-19 Positive Rates Amongst COVID-19 Close Contacts Through the Health Risk Warning System | E6: PR | F6: yes
A7: a29 | B7: D'Agostino, E.M., et al. | C7: 2022 | D7: Increasing access and uptake of SARS-CoV-2 at-home test using a community-engaged approach | E7: PR | F7: yes
A8: a30 | B8: Downs, L. O., et al | C8: 2021 | D8: Home-based SARS-CoV-2 lateral flow antigen testing in hospital workers | E8: PR | F8: yes
A9: a31 | B9: Du, Z., et al. | C9: 2022 | D9: Understanding the impact of rapid antigen tests on SARS-CoV-2 transmission in the fifth wave of COVID-19 in Hong Kong in early 2022 | E9: PR | F9: no
A10: a32 | B10: Engels, G., et al. | C10: 2022 | D10: Acceptance of different self-sampling methods for semiweekly SARS-CoV-2 testing in asymptomatic children and childcare workers at German day care centers | E10: PR | F10: yes
A11: a33 | B11: Gorgels, K.M.F. et al. | C11: 2024 | D11: Estimating infection prevalence using the positive predictive value of self-administered rapid antigen diagnostic tests: An exploration of SARS-CoV-2 surveillance data in the Netherlands from May 2021 to April 2022 | E11: PR | F11: no
A12: a34 | B12: Harmon, A. et al. | C12: 2021 | D12: Validation of an At-Home Direct Antigen Rapid Test for COVID-19 | E12: PR | F12: yes
A13: a35 | B13: Herbert, C., et al. (a) | C13: 2022 | D13: Design and Preliminary Findings of Adherence to the Self-Testing for Our Protection From COVID-19 (STOP COVID-19) Risk-Based Testing Protocol: Prospective Digital Study | E13: PR | F13: no
... A66: ## | B66: Pudasaini, S. et al. | C66: 2022 | D66: Feasibility of school music trips with safe cohorts during high SARS-CoV-2 incidence rates: a longitudinal observation study | E66: PP | F66: addition to a58 (Pudasaini et al.)

Sheet Quality assessment
A1: Identification | D1: Question 1 | G1: Question 2 | J1: Question 3 | M1: Question 4 | P1: Question 5 | S1: Question 6 | X1: Question 7 | AA1: Question 8 | AF1: Question 9 | AJ1: Summary of questions
A2: Study ID | B2: Sub_1 | C2: Author | D2: Test positivity | E2: Confirmat. Testing | F2: Partici-pation | G2: Test positivity | H2: Confirmat. Testing | I2: Partici-pation | J2: Test positivity | K2: Confirmat. Testing | L2: Partici-pation | M2: Test positivity | N2: Confirmat. Testing | O2: Partici-pation | P2: Test positivity | Q2: Confirmat. Testing | R2: Partici-pation | S2: Test positivity | T2: Confirmat. Testing | V2: Participation | X2: Test positivity | Y2: Confirmat. Testing | Z2: Partici-pation | AA2: Test positivity | AB2: Confirmat. Testing | AD2: Participation | AF2: Test positivity | AG2: Confirmat. Testing | AH2: Partici-pation | AJ2: Test positivity | AK2: Confirmat. Testing | AL2: Participation | AM2: Average
T3: Missed cases | U3: FP proportion | V3: Testing | W3: Reporting | AB3: Missed cases | AC3: FP proportion | AD3: Testing | AE3: Reporting
A4: a24 | B4: 1 | C4: Agusti, C., et al. | D4: yes | E4: n/a | F4: yes | G4: unclear | H4: n/a | I4: unclear | J4: unclear | K4: n/a | L4: unclear | M4: yes | N4: n/a | O4: yes | P4: no | Q4: n/a | R4: n/a | S4: yes | T4: n/a | U4: n/a | V4: yes | W4: yes | X4: yes | Y4: n/a | Z4: n/a | AA4: yes | AB4: n/a | AC4: n/a | AD4: yes | AE4: yes | AF4: yes | AG4: n/a | AH4: yes | AJ4: =IF(D4<>"n/a",(COUNTIF(D4,"yes")+COUNTIF(G4,"yes")+COUNTIF(J4,"yes")+COUNTIF(M4,"yes")+COUNTIF(P4,"yes")+COUNTIF(S4,"yes")+COUNTIF(X4,"yes")+COUNTIF(AA4,"yes")+COUNTIF(AF4,"yes"))/9,"#") -> 0.66666667 | AK4: =IF(E4<>"n/a",(COUNTIF(E4,"yes")+COUNTIF(H4,"yes")+COUNTIF(K4,"yes")+COUNTIF(N4,"yes")+COUNTIF(Q4,"yes")+IF(COUNTIF(T4:U4,"yes")>=1,1,0)+COUNTIF(Y4,"yes")+IF(COUNTIF(AB4:AC4,"yes")>=1,1,0)+COUNTIF(AG4,"yes"))/8,"#") -> # | AL4: =IF(F4<>"n/a",(COUNTIF(F4,"yes")+COUNTIF(I4,"yes")+COUNTIF(L4,"yes")+COUNTIF(O4,"yes")+COUNTIF(R4,"yes")+IF(COUNTIF(V4:W4,"yes")>=1,1,0)+COUNTIF(Z4,"yes")+IF(COUNTIF(AD4:AE4,"yes")>=1,1,0)+COUNTIF(AH4,"yes"))/7,"#") -> 0.71428571 | AM4: =AVERAGE(AJ4:AL4) -> 0.69047619
A5: a24 | B5: 2 | C5: Agusti, C., et al. | D5: yes | E5: n/a | F5: yes | G5: unclear | H5: n/a | I5: unclear | J5: unclear | K5: n/a | L5: unclear | M5: yes | N5: n/a | O5: yes | P5: no | Q5: n/a | R5: n/a | S5: yes | T5: n/a | U5: n/a | V5: yes | W5: yes | X5: yes | Y5: n/a | Z5: n/a | AA5: yes | AB5: n/a | AC5: n/a | AD5: yes | AE5: yes | AF5: yes | AG5: n/a | AH5: yes | AJ5: =IF(D5<>"n/a",(COUNTIF(D5,"yes")+COUNTIF(G5,"yes")+COUNTIF(J5,"yes")+COUNTIF(M5,"yes")+COUNTIF(P5,"yes")+COUNTIF(S5,"yes")+COUNTIF(X5,"yes")+COUNTIF(AA5,"yes")+COUNTIF(AF5,"yes"))/9,"#") -> 0.66666667 | AK5: =IF(E5<>"n/a",(COUNTIF(E5,"yes")+COUNTIF(H5,"yes")+COUNTIF(K5,"yes")+COUNTIF(N5,"yes")+COUNTIF(Q5,"yes")+IF(COUNTIF(T5:U5,"yes")>=1,1,0)+COUNTIF(Y5,"yes")+IF(COUNTIF(AB5:AC5,"yes")>=1,1,0)+COUNTIF(AG5,"yes"))/8,"#") -> # | AL5: =IF(F5<>"n/a",(COUNTIF(F5,"yes")+COUNTIF(I5,"yes")+COUNTIF(L5,"yes")+COUNTIF(O5,"yes")+COUNTIF(R5,"yes")+IF(COUNTIF(V5:W5,"yes")>=1,1,0)+COUNTIF(Z5,"yes")+IF(COUNTIF(AD5:AE5,"yes")>=1,1,0)+COUNTIF(AH5,"yes"))/7,"#") -> 0.71428571 | AM5: =AVERAGE(AJ5:AL5) -> 0.69047619
A6: a25 | B6: 0 | C6: Bresser, M., et al. | D6: yes | E6: n/a | F6: n/a | G6: unclear | H6: n/a | I6: n/a | J6: unclear | K6: n/a | L6: n/a | M6: yes | N6: n/a | O6: n/a | P6: no | Q6: n/a | R6: n/a | S6: yes | T6: n/a | U6: n/a | V6: n/a | W6: n/a | X6: yes | Y6: n/a | Z6: n/a | AA6: yes | AB6: n/a | AC6: n/a | AD6: n/a | AE6: n/a | AF6: yes | AG6: n/a | AH6: n/a | AJ6: =IF(D6<>"n/a",(COUNTIF(D6,"yes")+COUNTIF(G6,"yes")+COUNTIF(J6,"yes")+COUNTIF(M6,"yes")+COUNTIF(P6,"yes")+COUNTIF(S6,"yes")+COUNTIF(X6,"yes")+COUNTIF(AA6,"yes")+COUNTIF(AF6,"yes"))/9,"#") -> 0.66666667 | AK6: =IF(E6<>"n/a",(COUNTIF(E6,"yes")+COUNTIF(H6,"yes")+COUNTIF(K6,"yes")+COUNTIF(N6,"yes")+COUNTIF(Q6,"yes")+IF(COUNTIF(T6:U6,"yes")>=1,1,0)+COUNTIF(Y6,"yes")+IF(COUNTIF(AB6:AC6,"yes")>=1,1,0)+COUNTIF(AG6,"yes"))/8,"#") -> # | AL6: =IF(F6<>"n/a",(COUNTIF(F6,"yes")+COUNTIF(I6,"yes")+COUNTIF(L6,"yes")+COUNTIF(O6,"yes")+COUNTIF(R6,"yes")+IF(COUNTIF(V6:W6,"yes")>=1,1,0)+COUNTIF(Z6,"yes")+IF(COUNTIF(AD6:AE6,"yes")>=1,1,0)+COUNTIF(AH6,"yes"))/7,"#") -> # | AM6: =AVERAGE(AJ6:AL6) -> 0.66666667
A7: a26 | B7: 0 | C7: Chan, H.K., et al. | D7: yes | E7: n/a | F7: yes | G7: unclear | H7: n/a | I7: unclear | J7: unclear | K7: n/a | L7: unclear | M7: yes | N7: n/a | O7: yes | P7: unclear | Q7: n/a | R7: n/a | S7: yes | T7: n/a | U7: n/a | V7: yes | W7: yes | X7: no | Y7: n/a | Z7: n/a | AA7: no | AB7: n/a | AC7: n/a | AD7: yes | AE7: no | AF7: yes | AG7: n/a | AH7: yes | AJ7: =IF(D7<>"n/a",(COUNTIF(D7,"yes")+COUNTIF(G7,"yes")+COUNTIF(J7,"yes")+COUNTIF(M7,"yes")+COUNTIF(P7,"yes")+COUNTIF(S7,"yes")+COUNTIF(X7,"yes")+COUNTIF(AA7,"yes")+COUNTIF(AF7,"yes"))/9,"#") -> 0.44444444 | AK7: =IF(E7<>"n/a",(COUNTIF(E7,"yes")+COUNTIF(H7,"yes")+COUNTIF(K7,"yes")+COUNTIF(N7,"yes")+COUNTIF(Q7,"yes")+IF(COUNTIF(T7:U7,"yes")>=1,1,0)+COUNTIF(Y7,"yes")+IF(COUNTIF(AB7:AC7,"yes")>=1,1,0)+COUNTIF(AG7,"yes"))/8,"#") -> # | AL7: =IF(F7<>"n/a",(COUNTIF(F7,"yes")+COUNTIF(I7,"yes")+COUNTIF(L7,"yes")+COUNTIF(O7,"yes")+COUNTIF(R7,"yes")+IF(COUNTIF(V7:W7,"yes")>=1,1,0)+COUNTIF(Z7,"yes")+IF(COUNTIF(AD7:AE7,"yes")>=1,1,0)+COUNTIF(AH7,"yes"))/7,"#") -> 0.71428571 | AM7: =AVERAGE(AJ7:AL7) -> 0.57936508
A8: a28 | B8: 1 | C8: Chong, S.J., et al. | D8: yes | E8: n/a | F8: n/a | G8: unclear | H8: n/a | I8: n/a | J8: unclear | K8: n/a | L8: n/a | M8: yes | N8: n/a | O8: n/a | P8: yes | Q8: n/a | R8: n/a | S8: unclear | T8: n/a | U8: n/a | V8: n/a | W8: n/a | X8: no | Y8: n/a | Z8: n/a | AA8: unclear | AB8: n/a | AC8: n/a | AD8: n/a | AE8: n/a | AF8: yes | AG8: n/a | AH8: n/a | AJ8: =IF(D8<>"n/a",(COUNTIF(D8,"yes")+COUNTIF(G8,"yes")+COUNTIF(J8,"yes")+COUNTIF(M8,"yes")+COUNTIF(P8,"yes")+COUNTIF(S8,"yes")+COUNTIF(X8,"yes")+COUNTIF(AA8,"yes")+COUNTIF(AF8,"yes"))/9,"#") -> 0.44444444 | AK8: =IF(E8<>"n/a",(COUNTIF(E8,"yes")+COUNTIF(H8,"yes")+COUNTIF(K8,"yes")+COUNTIF(N8,"yes")+COUNTIF(Q8,"yes")+IF(COUNTIF(T8:U8,"yes")>=1,1,0)+COUNTIF(Y8,"yes")+IF(COUNTIF(AB8:AC8,"yes")>=1,1,0)+COUNTIF(AG8,"yes"))/8,"#") -> # | AL8: =IF(F8<>"n/a",(COUNTIF(F8,"yes")+COUNTIF(I8,"yes")+COUNTIF(L8,"yes")+COUNTIF(O8,"yes")+COUNTIF(R8,"yes")+IF(COUNTIF(V8:W8,"yes")>=1,1,0)+COUNTIF(Z8,"yes")+IF(COUNTIF(AD8:AE8,"yes")>=1,1,0)+COUNTIF(AH8,"yes"))/7,"#") -> # | AM8: =AVERAGE(AJ8:AL8) -> 0.44444444
A9: a28 | B9: 2 | C9: Chong, S.J., et al. | D9: yes | E9: n/a | F9: n/a | G9: unclear | H9: n/a | I9: n/a | J9: unclear | K9: n/a | L9: n/a | M9: yes | N9: n/a | O9: n/a | P9: yes | Q9: n/a | R9: n/a | S9: unclear | T9: n/a | U9: n/a | V9: n/a | W9: n/a | X9: no | Y9: n/a | Z9: n/a | AA9: unclear | AB9: n/a | AC9: n/a | AD9: n/a | AE9: n/a | AF9: yes | AG9: n/a | AH9: n/a | AJ9: =IF(D9<>"n/a",(COUNTIF(D9,"yes")+COUNTIF(G9,"yes")+COUNTIF(J9,"yes")+COUNTIF(M9,"yes")+COUNTIF(P9,"yes")+COUNTIF(S9,"yes")+COUNTIF(X9,"yes")+COUNTIF(AA9,"yes")+COUNTIF(AF9,"yes"))/9,"#") -> 0.44444444 | AK9: =IF(E9<>"n/a",(COUNTIF(E9,"yes")+COUNTIF(H9,"yes")+COUNTIF(K9,"yes")+COUNTIF(N9,"yes")+COUNTIF(Q9,"yes")+IF(COUNTIF(T9:U9,"yes")>=1,1,0)+COUNTIF(Y9,"yes")+IF(COUNTIF(AB9:AC9,"yes")>=1,1,0)+COUNTIF(AG9,"yes"))/8,"#") -> # | AL9: =IF(F9<>"n/a",(COUNTIF(F9,"yes")+COUNTIF(I9,"yes")+COUNTIF(L9,"yes")+COUNTIF(O9,"yes")+COUNTIF(R9,"yes")+IF(COUNTIF(V9:W9,"yes")>=1,1,0)+COUNTIF(Z9,"yes")+IF(COUNTIF(AD9:AE9,"yes")>=1,1,0)+COUNTIF(AH9,"yes"))/7,"#") -> # | AM9: =AVERAGE(AJ9:AL9) -> 0.44444444
A10: a28 | B10: 3 | C10: Chong, S.J., et al. | D10: yes | E10: n/a | F10: n/a | G10: unclear | H10: n/a | I10: n/a | J10: unclear | K10: n/a | L10: n/a | M10: yes | N10: n/a | O10: n/a | P10: yes | Q10: n/a | R10: n/a | S10: unclear | T10: n/a | U10: n/a | V10: n/a | W10: n/a | X10: no | Y10: n/a | Z10: n/a | AA10: unclear | AB10: n/a | AC10: n/a | AD10: n/a | AE10: n/a | AF10: yes | AG10: n/a | AH10: n/a | AJ10: =IF(D10<>"n/a",(COUNTIF(D10,"yes")+COUNTIF(G10,"yes")+COUNTIF(J10,"yes")+COUNTIF(M10,"yes")+COUNTIF(P10,"yes")+COUNTIF(S10,"yes")+COUNTIF(X10,"yes")+COUNTIF(AA10,"yes")+COUNTIF(AF10,"yes"))/9,"#") -> 0.44444444 | AK10: =IF(E10<>"n/a",(COUNTIF(E10,"yes")+COUNTIF(H10,"yes")+COUNTIF(K10,"yes")+COUNTIF(N10,"yes")+COUNTIF(Q10,"yes")+IF(COUNTIF(T10:U10,"yes")>=1,1,0)+COUNTIF(Y10,"yes")+IF(COUNTIF(AB10:AC10,"yes")>=1,1,0)+COUNTIF(AG10,"yes"))/8,"#") -> # | AL10: =IF(F10<>"n/a",(COUNTIF(F10,"yes")+COUNTIF(I10,"yes")+COUNTIF(L10,"yes")+COUNTIF(O10,"yes")+COUNTIF(R10,"yes")+IF(COUNTIF(V10:W10,"yes")>=1,1,0)+COUNTIF(Z10,"yes")+IF(COUNTIF(AD10:AE10,"yes")>=1,1,0)+COUNTIF(AH10,"yes"))/7,"#") -> # | AM10: =AVERAGE(AJ10:AL10) -> 0.44444444
A11: a28 | B11: 4 | C11: Chong, S.J., et al. | D11: yes | E11: n/a | F11: n/a | G11: unclear | H11: n/a | I11: n/a | J11: unclear | K11: n/a | L11: n/a | M11: yes | N11: n/a | O11: n/a | P11: yes | Q11: n/a | R11: n/a | S11: unclear | T11: n/a | U11: n/a | V11: n/a | W11: n/a | X11: no | Y11: n/a | Z11: n/a | AA11: no | AB11: n/a | AC11: n/a | AD11: n/a | AE11: n/a | AF11: yes | AG11: n/a | AH11: n/a | AJ11: =IF(D11<>"n/a",(COUNTIF(D11,"yes")+COUNTIF(G11,"yes")+COUNTIF(J11,"yes")+COUNTIF(M11,"yes")+COUNTIF(P11,"yes")+COUNTIF(S11,"yes")+COUNTIF(X11,"yes")+COUNTIF(AA11,"yes")+COUNTIF(AF11,"yes"))/9,"#") -> 0.44444444 | AK11: =IF(E11<>"n/a",(COUNTIF(E11,"yes")+COUNTIF(H11,"yes")+COUNTIF(K11,"yes")+COUNTIF(N11,"yes")+COUNTIF(Q11,"yes")+IF(COUNTIF(T11:U11,"yes")>=1,1,0)+COUNTIF(Y11,"yes")+IF(COUNTIF(AB11:AC11,"yes")>=1,1,0)+COUNTIF(AG11,"yes"))/8,"#") -> # | AL11: =IF(F11<>"n/a",(COUNTIF(F11,"yes")+COUNTIF(I11,"yes")+COUNTIF(L11,"yes")+COUNTIF(O11,"yes")+COUNTIF(R11,"yes")+IF(COUNTIF(V11:W11,"yes")>=1,1,0)+COUNTIF(Z11,"yes")+IF(COUNTIF(AD11:AE11,"yes")>=1,1,0)+COUNTIF(AH11,"yes"))/7,"#") -> # | AM11: =AVERAGE(AJ11:AL11) -> 0.44444444
A12: a29 | B12: 0 | C12: D'Agostino, E.M., et al. | D12: yes | E12: n/a | F12: n/a | G12: unclear | H12: n/a | I12: n/a | J12: unclear | K12: n/a | L12: n/a | M12: yes | N12: n/a | O12: n/a | P12: unclear | Q12: n/a | R12: n/a | S12: yes | T12: n/a | U12: n/a | V12: n/a | W12: n/a | X12: unclear | Y12: n/a | Z12: n/a | AA12: unclear | AB12: n/a | AC12: n/a | AD12: n/a | AE12: n/a | AF12: yes | AG12: n/a | AH12: n/a | AJ12: =IF(D12<>"n/a",(COUNTIF(D12,"yes")+COUNTIF(G12,"yes")+COUNTIF(J12,"yes")+COUNTIF(M12,"yes")+COUNTIF(P12,"yes")+COUNTIF(S12,"yes")+COUNTIF(X12,"yes")+COUNTIF(AA12,"yes")+COUNTIF(AF12,"yes"))/9,"#") -> 0.44444444 | AK12: =IF(E12<>"n/a",(COUNTIF(E12,"yes")+COUNTIF(H12,"yes")+COUNTIF(K12,"yes")+COUNTIF(N12,"yes")+COUNTIF(Q12,"yes")+IF(COUNTIF(T12:U12,"yes")>=1,1,0)+COUNTIF(Y12,"yes")+IF(COUNTIF(AB12:AC12,"yes")>=1,1,0)+COUNTIF(AG12,"yes"))/8,"#") -> # | AL12: =IF(F12<>"n/a",(COUNTIF(F12,"yes")+COUNTIF(I12,"yes")+COUNTIF(L12,"yes")+COUNTIF(O12,"yes")+COUNTIF(R12,"yes")+IF(COUNTIF(V12:W12,"yes")>=1,1,0)+COUNTIF(Z12,"yes")+IF(COUNTIF(AD12:AE12,"yes")>=1,1,0)+COUNTIF(AH12,"yes"))/7,"#") -> # | AM12: =AVERAGE(AJ12:AL12) -> 0.44444444
A13: a30 | B13: 0 | C13: Downs, L.O., et al | D13: yes | E13: n/a | F13: yes | G13: unclear | H13: n/a | I13: unclear | J13: unclear | K13: n/a | L13: unclear | M13: yes | N13: n/a | O13: yes | P13: yes | Q13: n/a | R13: n/a | S13: yes | T13: n/a | U13: n/a | V13: n/a | W13: yes | X13: no | Y13: n/a | Z13: n/a | AA13: unclear | AB13: n/a | AC13: n/a | AD13: n/a | AE13: no | AF13: yes | AG13: n/a | AH13: yes | AJ13: =IF(D13<>"n/a",(COUNTIF(D13,"yes")+COUNTIF(G13,"yes")+COUNTIF(J13,"yes")+COUNTIF(M13,"yes")+COUNTIF(P13,"yes")+COUNTIF(S13,"yes")+COUNTIF(X13,"yes")+COUNTIF(AA13,"yes")+COUNTIF(AF13,"yes"))/9,"#") -> 0.55555556 | AK13: =IF(E13<>"n/a",(COUNTIF(E13,"yes")+COUNTIF(H13,"yes")+COUNTIF(K13,"yes")+COUNTIF(N13,"yes")+COUNTIF(Q13,"yes")+IF(COUNTIF(T13:U13,"yes")>=1,1,0)+COUNTIF(Y13,"yes")+IF(COUNTIF(AB13:AC13,"yes")>=1,1,0)+COUNTIF(AG13,"yes"))/8,"#") -> # | AL13: =IF(F13<>"n/a",(COUNTIF(F13,"yes")+COUNTIF(I13,"yes")+COUNTIF(L13,"yes")+COUNTIF(O13,"yes")+COUNTIF(R13,"yes")+IF(COUNTIF(V13:W13,"yes")>=1,1,0)+COUNTIF(Z13,"yes")+IF(COUNTIF(AD13:AE13,"yes")>=1,1,0)+COUNTIF(AH13,"yes"))/7,"#") -> 0.57142857 | AM13: =AVERAGE(AJ13:AL13) -> 0.56349206
A14: a32 | B14: 1 | C14: Engels, G., et al. | D14: yes | E14: n/a | F14: yes | G14: unclear | H14: n/a | I14: unclear | J14: unclear | K14: n/a | L14: unclear | M14: yes | N14: n/a | O14: yes | P14: yes | Q14: n/a | R14: n/a | S14: yes | T14: n/a | U14: n/a | V14: yes | W14: yes | X14: no | Y14: n/a | Z14: n/a | AA14: no | AB14: n/a | AC14: n/a | AD14: unclear | AE14: unclear | AF14: yes | AG14: n/a | AH14: yes | AJ14: =IF(D14<>"n/a",(COUNTIF(D14,"yes")+COUNTIF(G14,"yes")+COUNTIF(J14,"yes")+COUNTIF(M14,"yes")+COUNTIF(P14,"yes")+COUNTIF(S14,"yes")+COUNTIF(X14,"yes")+COUNTIF(AA14,"yes")+COUNTIF(AF14,"yes"))/9,"#") -> 0.55555556 | AK14: =IF(E14<>"n/a",(COUNTIF(E14,"yes")+COUNTIF(H14,"yes")+COUNTIF(K14,"yes")+COUNTIF(N14,"yes")+COUNTIF(Q14,"yes")+IF(COUNTIF(T14:U14,"yes")>=1,1,0)+COUNTIF(Y14,"yes")+IF(COUNTIF(AB14:AC14,"yes")>=1,1,0)+COUNTIF(AG14,"yes"))/8,"#") -> # | AL14: =IF(F14<>"n/a",(COUNTIF(F14,"yes")+COUNTIF(I14,"yes")+COUNTIF(L14,"yes")+COUNTIF(O14,"yes")+COUNTIF(R14,"yes")+IF(COUNTIF(V14:W14,"yes")>=1,1,0)+COUNTIF(Z14,"yes")+IF(COUNTIF(AD14:AE14,"yes")>=1,1,0)+COUNTIF(AH14,"yes"))/7,"#") -> 0.57142857 | AM14: =AVERAGE(AJ14:AL14) -> 0.56349206
A15: a32 | B15: 2 | C15: Engels, G., et al. | D15: yes | E15: n/a | F15: yes | G15: unclear | H15: n/a | I15: unclear | J15: unclear | K15: n/a | L15: unclear | M15: yes | N15: n/a | O15: yes | P15: yes | Q15: n/a | R15: n/a | S15: yes | T15: n/a | U15: n/a | V15: yes | W15: yes | X15: no | Y15: n/a | Z15: n/a | AA15: no | AB15: n/a | AC15: n/a | AD15: unclear | AE15: unclear | AF15: yes | AG15: n/a | AH15: yes | AJ15: =IF(D15<>"n/a",(COUNTIF(D15,"yes")+COUNTIF(G15,"yes")+COUNTIF(J15,"yes")+COUNTIF(M15,"yes")+COUNTIF(P15,"yes")+COUNTIF(S15,"yes")+COUNTIF(X15,"yes")+COUNTIF(AA15,"yes")+COUNTIF(AF15,"yes"))/9,"#") -> 0.55555556 | AK15: =IF(E15<>"n/a",(COUNTIF(E15,"yes")+COUNTIF(H15,"yes")+COUNTIF(K15,"yes")+COUNTIF(N15,"yes")+COUNTIF(Q15,"yes")+IF(COUNTIF(T15:U15,"yes")>=1,1,0)+COUNTIF(Y15,"yes")+IF(COUNTIF(AB15:AC15,"yes")>=1,1,0)+COUNTIF(AG15,"yes"))/8,"#") -> # | AL15: =IF(F15<>"n/a",(COUNTIF(F15,"yes")+COUNTIF(I15,"yes")+COUNTIF(L15,"yes")+COUNTIF(O15,"yes")+COUNTIF(R15,"yes")+IF(COUNTIF(V15:W15,"yes")>=1,1,0)+COUNTIF(Z15,"yes")+IF(COUNTIF(AD15:AE15,"yes")>=1,1,0)+COUNTIF(AH15,"yes"))/7,"#") -> 0.57142857 | AM15: =AVERAGE(AJ15:AL15) -> 0.56349206
... A77: a84 | B77: 0 | C77: Qasmieh, S.A. et al. (c) | D77: n/a | E77: n/a | F77: yes | G77: n/a | H77: n/a | I77: unclear | J77: n/a | K77: n/a | L77: unclear | M77: n/a | N77: n/a | O77: yes | P77: n/a | Q77: n/a | R77: n/a | S77: n/a | T77: n/a | U77: n/a | V77: yes | W77: n/a | X77: n/a | Y77: n/a | Z77: n/a | AA77: n/a | AB77: n/a | AC77: n/a | AD77: unclear | AE77: n/a | AF77: n/a | AG77: n/a | AH77: yes | AJ77: =IF(D77<>"n/a",(COUNTIF(D77,"yes")+COUNTIF(G77,"yes")+COUNTIF(J77,"yes")+COUNTIF(M77,"yes")+COUNTIF(P77,"yes")+COUNTIF(S77,"yes")+COUNTIF(X77,"yes")+COUNTIF(AA77,"yes")+COUNTIF(AF77,"yes"))/9,"#") -> # | AK77: =IF(E77<>"n/a",(COUNTIF(E77,"yes")+COUNTIF(H77,"yes")+COUNTIF(K77,"yes")+COUNTIF(N77,"yes")+COUNTIF(Q77,"yes")+IF(COUNTIF(T77:U77,"yes")>=1,1,0)+COUNTIF(Y77,"yes")+IF(COUNTIF(AB77:AC77,"yes")>=1,1,0)+COUNTIF(AG77,"yes"))/8,"#") -> # | AL77: =IF(F77<>"n/a",(COUNTIF(F77,"yes")+COUNTIF(I77,"yes")+COUNTIF(L77,"yes")+COUNTIF(O77,"yes")+COUNTIF(R77,"yes")+IF(COUNTIF(V77:W77,"yes")>=1,1,0)+COUNTIF(Z77,"yes")+IF(COUNTIF(AD77:AE77,"yes")>=1,1,0)+COUNTIF(AH77,"yes"))/7,"#") -> 0.57142857 | AM77: =AVERAGE(AJ77:AL77) -> 0.57142857
A80: No meta-analyzable outcome
A81: a27 | B81: 1 | C81: Chen, S.H., et al. | AJ81: =AVERAGE(AJ4:AJ77) -> 0.53571429 | AK81: =AVERAGE(AK4:AK77) -> 0.75 | AL81: =AVERAGE(AL4:AL77) -> 0.61185984 | AM81: =AVERAGE(AM4:AM77) -> 0.57564708 | AN81: # of data sets
A82: a27 | B82: 2 | C82: Chen, S.H., et al.
A83: a31 | B83: 0 | C83: Du, Z., et al.
A84: a33 | B84: 0 | C84: Gorgels, K.M.F., et al. | AI84: # <60% | AJ84: =COUNTIF(AJ$4:AJ$77,"<0.6")/COUNT(AJ$4:AJ$77) -> 0.71428571 | AK84: =COUNTIF(AK$4:AK$77,"<0.6")/COUNT(AK$4:AK$77) -> 0 | AL84: =COUNTIF(AL$4:AL$77,"<0.6")/COUNT(AL$4:AL$77) -> 0.62264151 | AM84: =COUNTIF(AM$4:AM$77,"<0.6")/COUNT(AM$4:AM$77) -> 0.63513514 | AN84: =COUNT(AM4:AM77)*AM84 -> 47
A85: a35 | B85: 2 | C85: Herbert, C., et al. (a) | AI85: # 60-80% | AJ85: =COUNTIF(AJ$4:AJ$77,"<=0.8")/COUNT(AJ$4:AJ$77)-AJ$84 -> 0.28571429 | AK85: =COUNTIF(AK$4:AK$77,"<=0.8")/COUNT(AK$4:AK$77)-AK$84 -> 1 | AL85: =COUNTIF(AL$4:AL$77,"<=0.8")/COUNT(AL$4:AL$77)-AL$84 -> 0.37735849 | AM85: =COUNTIF(AM$4:AM$77,"<=0.8")/COUNT(AM$4:AM$77)-AM$84 -> 0.36486486 | AN85: =COUNT(AM4:AM77)*AM85 -> 27
A86: a42 | B86: 0 | C86: Kheiroddin, P., et al. | AI86: # >80% | AJ86: =COUNTIF(AJ$4:AJ$77,">0.8")/COUNT(AJ$4:AJ$77) -> 0 | AK86: =COUNTIF(AK$4:AK$77,">0.8")/COUNT(AK$4:AK$77) -> 0 | AL86: =COUNTIF(AL$4:AL$77,">0.8")/COUNT(AL$4:AL$77) -> 0 | AM86: =COUNTIF(AM$4:AM$77,">0.8")/COUNT(AM$4:AM$77) -> 0 | AN86: =COUNT(AM4:AM77)*AM86 -> 0
A87: a53 | B87: 0 | C87: Moonan, P.K., et al.
A88: a54 | B88: 0 | C88: Nagasawa, M., et al. | AI88: # <60% | AJ88: =COUNTIF(AJ$4:AJ$77,"<0.6") -> 40 | AK88: =COUNTIF(AK$4:AK$77,"<0.6") -> 0 | AL88: =COUNTIF(AL$4:AL$77,"<0.6") -> 33 | AM88: =COUNTIF(AM$4:AM$77,"<0.6") -> 47 | AN88: =AM88 -> 47
A89: a61 | B89: 0 | C89: Soni, A., et al. (a) | AI89: # 60-80% | AJ89: =COUNTIF(AJ$4:AJ$77,"<=0.8")-AJ88 -> 16 | AK89: =COUNTIF(AK$4:AK$77,"<=0.8")-AK88 -> 11 | AL89: =COUNTIF(AL$4:AL$77,"<=0.8")-AL88 -> 20 | AM89: =COUNTIF(AM$4:AM$77,"<=0.8")-AM88 -> 27 | AN89: =AM89 -> 27
A90: a70 | B90: 2 | C90: U. o. Liverpool | AI90: # >80% | AJ90: =COUNTIF(AJ$4:AJ$77,">0.8") -> 0 | AK90: =COUNTIF(AK$4:AK$77,">0.8") -> 0 | AL90: =COUNTIF(AL$4:AL$77,">0.8") -> 0 | AM90: =COUNTIF(AM$4:AM$77,">0.8") -> 0 | AN90: =AM90 -> 0
A91: a73 | B91: 0 | C91: Wong, S.C., et al.
A92: a81 | B92: 1 | C92: Stirrup, O. et al. | AI92: SUM | AJ92: =SUM(AJ88:AJ90) -> 56 | AK92: =SUM(AK88:AK90) -> 11 | AL92: =SUM(AL88:AL90) -> 53 | AM92: =SUM(AM88:AM90) -> 74 | AN92: =SUM(AN88:AN90) -> 74
A93: a81 | B93: 2 | C93: Stirrup, O. et al.

Sheet Data extracted
A1: Identification | C1: Study Characteristics | AJ1: Testing Characteristics | BY1: Individual level health outcome | CK1: Community level health outcome | DE1: Include in analysis | DG1: Sensitivity analyses
C2: General | K2: Number of study participants | P2: Characteristics study population | AJ2: Ag-RDT implementation | AY2: Ag-RDT result - in number of tests | BD2: Confirmatory testing - in number of tests | BL2: Ag-RDT result - in number of people | BQ2: Confirmatory testing - in number of people | BY2: Actions after Ag-RDT result | CE2: Undesirable Effects | CI2: Individual level health impact | CK2: Transmission | CS2: Population health benefits | CU2: Health system effects | CX2: Broader societal effects
A3: Study ID | B3: Author | C3: Type | D3: Start Date | E3: End Date | F3: Location | G3: Location details | H3: Community | I3: 2025 GDP per Capita | J3: Costs for study participants | K3: Number of people eligible / invited for self-testing | L3: Number of people that collected / were sent self-tests | M3: Number of people that reported self-testing results | N3: Max | O3: Population included in study based on … | P3: Age (mean) | Q3: Age (SD) | R3: Age (median) | S3: Age (Q1) | T3: Age (Q3) | U3: Age (u range) | V3: Age (l range) | W3: Females | X3: Males | Y3: Other / unknown sex | Z3: Target population | AA3: Symptomatic individuals | AB3: Asymptomatic individuals | AC3: Unknown symptom status | AD3: Overview symptom status | AE3: Risk Factors | AF3: SARS-CoV-2 Exposure | AG3: SARS-CoV-2 status | AH3: Vaccination status | AI3: Seroconvalescence status | AJ3: Ag-RDT name | AK3: Reader | AL3: Sample Type | AM3: Test distributer | AN3: Testing site | AO3: Frequency of Testing | AP3: Times per week | AQ3: Duration in weeks | AR3: Optimal # of tests performed as per testing scheme | AS3: Number of self-tests performed | AT3: Number of results reported | AU3: Assistance | AV3: Supervision | AW3: Additional interventions | AX3: Continue after positive confirmatory test result? | AY3: Ag-RDT_n tests_SUM | AZ3: Ag-RDT_n tests_Positive | BA3: Ag-RDT_n tests_Negative | BB3: Ag-RDT_n tests_Invalid | BC3: Ag-RDT_n tests_False Interpretation | BD3: Confirm_n tests_Type | BE3: Confirm_n tests_Sample type | BF3: Confirm_n tests_Total | BG3: Confirm_n tests_TP | BH3: Confirm_n tests_FN | BI3: Confirm_n tests_TN | BJ3: Confirm_n tests_FP | BK3: Confirm_n_tests_FP_ref | BL3: Ag-RDT_n people_SUM | BM3: Ag-RDT_n people_Positive | BN3: Ag-RDT_n people_Negative | BO3: Ag-RDT_n people_Invalid | BP3: Ag-RDT_n people_False Interpretation | BQ3: Confirm_n people_Type | BR3: Confirm_n people_Sample type | BS3: Confirm_n people_Total | BT3: Confirm_n people_TP | BU3: Confirm_n people_FN | BV3: Confirm_n people_TN | BW3: Confirm_n people_FP | BX3: Confirm_n people_FN_ref | BY3: Tool to diagnose | BZ3: Time to diagnosis | CA3: Time to decision | CB3: Ag-RDT positive result | CC3: RT-PCR follow up | CD3: Ag-RDT negative result | CE3: Use out of the intended | CF3: Fabrication of Data | CG3: Social Harm | CH3: Adverse Events | CI3: Hospitalization | CJ3: Disease Severity | CK3: Incidence | CL3: Prevalence | CM3: Cases Averted | CN3: Tertiary cases | CO3: Tertiary cases_denominator | CP3: Tertiary cases_comparator | CQ3: Tertiary cases_denominator_comparator | CR3: Tertiary contacts | CS3: Deaths Averted | CT3: Morbidity Averted | CU3: Hospitalization | CV3: ICU occupancy | CW3: Transmission within health care workers | CX3: School / Work Operations | CY3: Quarantine Duration | CZ3: Wellbeing | DA3: Absenteeism | DB3: Resource Usage | DC3: User Costs | DD3: Time Savings | DE3: FP_analysis | DF3: Missed_analysis | DG3: SA_Uptake | DH3: SA_Reporting | DI3: Behaviour change
A4: a24_1 | B4: Agusti, C., et al. | C4: prosp. cohort | D4: 44545 | E4: 44607 | F4: Spain | G4: EU; Staff of the Catalan Institute of Oncology | H4: City; semi-dense | I4: 38039.876 | J4: unclear | K4: 1400 | L4: 195 | M4: 111 | N4: =MAX(K4:M4) -> 1400 | O4: Number of people that reported self-testing results | P4: # | Q4: # | R4: 42.8 | S4: 32.4 | T4: 53.2 | U4: # | V4: # | W4: 91 | X4: 20 | Y4: 0 | Z4: Healthcare Professionals | AA4: 21 | AB4: 89 | AC4: 1 | AD4: =IF(AND(AA4=0,AC4=0),1,0) -> 0 | AE4: # | AF4: # | AG4: unknown | AH4: 110 are vaccinated, 1 not | AI4: # | AJ4: Panbio Antigen self-test, Abbot | AK4: no | AL4: AN / MT | AM4: unclear | AN4: Home | AO4: Single | AP4: # | AQ4: # | AR4: 195 | AS4: # | AT4: 111 | AU4: no | AV4: no | AW4: unclear | AX4: # | AY4: =SUM(AZ4:BC4) -> 111 | AZ4: 4 | BA4: =111-AZ4 -> 107 | BB4: 0 | BC4: # | BD4: # | BE4: # | BF4: =SUM(BG4:BJ4) -> 0 | BG4: # | BH4: # | BI4: # | BJ4: # | BK4: =IFERROR(IF(BJ4<>"#",BJ4+BI4,"#"),"#") -> # | BL4: =SUM(BM4:BP4) -> 111 | BM4: 4 | BN4: =111-BM4 -> 107 | BO4: 0 | BP4: # | BQ4: # | BR4: # | BS4: =SUM(BT4:BW4) -> 0 | BT4: # | BU4: # | BV4: # | BW4: # | BX4: =IFERROR(IF(BU4<>"#",BU4+BT4,"#"),"#") -> # | BY4: # | BZ4: # | CA4: test result available within a few minutes | CB4: Recommendation to self-isolate and contact general practitioner (GP) as soon as possible | CC4: # | CD4: # | CE4: # | CF4: # | CG4: # | CH4: # | CI4: # | CJ4: # | CK4: # | CL4: # | CM4: # | CN4: # | CO4: # | CP4: # | CQ4: # | CR4: # | CS4: # | CT4: # | CU4: # | CV4: # | CW4: # | CX4: # | CY4: # | CZ4: 81.1% (90) of participants felt self-test can improve security and protection of COVID-19 in the workplace and 44.1% (49) found the option to perform self-testing in privat / confidentially an advantage | DA4: # | DB4: # | DC4: 61.3% (68) of study participants found self-testing being availbae for free to be an advantage of self-testing | DD4: # | DE4: # | DF4: # | DG4: # | DH4: # | DI4: #
A5: a24_2 | B5: Agusti, C., et al. | C5: prosp. cohort | D5: 44545 | E5: 44607 | F5: Spain | G5: EU; Staff of the schools belonging to the COVID Sentinel School Network of Catalonia | H5: City; semi-dense | I5: 38039.876 | J5: unclear | K5: 700 | L5: 297 | M5: 192 | N5: =MAX(K5:M5) -> 700 | O5: Number of people that reported self-testing results | P5: # | Q5: # | R5: 42.1 | S5: 31.8 | T5: 52.4 | U5: # | V5: # | W5: 155 | X5: 39 | Y5: 2 | Z5: K-12 students and staff | AA5: 42 | AB5: 152 | AC5: 2 | AD5: =IF(AND(AA5=0,AC5=0),1,0) -> 0 | AE5: # | AF5: # | AG5: unknown | AH5: 193 are vaccinated, 2 not, 1 unclear | AI5: # | AJ5: Panbio Antigen self-test, Abbot | AK5: no | AL5: AN / MT | AM5: unclear | AN5: Home | AO5: Single | AP5: # | AQ5: # | AR5: 297 | AS5: # | AT5: 192 | AU5: no | AV5: no | AW5: unclear | AX5: # | AY5: =SUM(AZ5:BC5) -> 192 | AZ5: 14 | BA5: =192-AZ5 -> 178 | BB5: 0 | BC5: # | BD5: # | BE5: # | BF5: =SUM(BG5:BJ5) -> 0 | BG5: # | BH5: # | BI5: # | BJ5: # | BK5: =IFERROR(IF(BJ5<>"#",BJ5+BI5,"#"),"#") -> # | BL5: =SUM(BM5:BP5) -> 192 | BM5: 14 | BN5: =192-BM5 -> 178 | BO5: 0 | BP5: # | BQ5: # | BR5: # | BS5: =SUM(BT5:BW5) -> 0 | BT5: # | BU5: # | BV5: # | BW5: # | BX5: =IFERROR(IF(BU5<>"#",BU5+BT5,"#"),"#") -> # | BY5: # | BZ5: # | CA5: test result available within a few minutes | CB5: Recommendation to self-isolate and contact general practitioner (GP) as soon as possible | CC5: # | CD5: # | CE5: # | CF5: # | CG5: # | CH5: # | CI5: # | CJ5: # | CK5: # | CL5: # | CM5: # | CN5: # | CO5: # | CP5: # | CQ5: # | CR5: # | CS5: # | CT5: # | CU5: # | CV5: # | CW5: # | CX5: # | CY5: # | CZ5: 86.7% (170) of participants felt self-test can improve security and protection of COVID-19 in the workplace and 31.6% (62) found the option to perform self-testing in privat / confidentially an advantage | DA5: # | DB5: # | DC5: 64.8% (127) of study participants found self-testing being availbae for free to be an advantage of self-testing | DD5: # | DE5: # | DF5: # | DG5: # | DH5: # | DI5: #
A6: a25_0 | B6: Bresser, M., et al. | C6: prosp. cohort | D6: 44607 | E6: 44666 | F6: Zambia | G6: Other; Individuals near Kabwe town in Central Province | H6: Semi-dense | I6: 1352.989 | J6: unclear | K6: # | L6: # | M6: 1123 | N6: =MAX(K6:M6) -> 1123 | O6: Number of people that collected / were sent self-tests | P6: # | Q6: # | R6: 27 | S6: 21 | T6: 37 | U6: # | V6: # | W6: 432 | X6: # | Y6: # | Z6: General population | AA6: 199 | AB6: 937 | AC6: 0 | AD6: =IF(AND(AA6=0,AC6=0),1,0) -> 0 | AE6: 50 are PLHIV, of which 41 are on ART; 1059 are HIV negative and 4 have unknown HIV status; 4 on TB treatment | AF6: # | AG6: unknown | AH6: # | AI6: # | AJ6: Standard Q | AK6: no | AL6: AN / MT | AM6: Testing Site | AN6: Home / Testing Site | AO6: Single | AP6: # | AQ6: # | AR6: # | AS6: # | AT6: 1121 | AU6: no | AV6: yes | AW6: # | AX6: # | AY6: =SUM(AZ6:BC6) -> 1123 | AZ6: 9 | BA6: 1109 | BB6: 5 | BC6: # | BD6: Professional Ag-RDT testing | BE6: # | BF6: =SUM(BG6:BJ6) -> 1118 | BG6: 9 | BH6: 2 | BI6: 1107 | BJ6: 0 | BK6: =IFERROR(IF(BJ6<>"#",BJ6+BI6,"#"),"#") -> 1107 | BL6: =SUM(BM6:BP6) -> 1123 | BM6: 9 | BN6: 1109 | BO6: 5 | BP6: # | BQ6: Professional Ag-RDT testing | BR6: # | BS6: =SUM(BT6:BW6) -> 1118 | BT6: 9 | BU6: 2 | BV6: 1107 | BW6: # | BX6: =IFERROR(IF(BU6<>"#",BU6+BT6,"#"),"#") -> 11 | BY6: C19ST or Ag-RDT professional test | BZ6: 15 min | CA6: # | CB6: Follow national COVID-19 guideline | CC6: # | CD6: # | CE6: # | CF6: # | CG6: # | CH6: # | CI6: # | CJ6: # | CK6: # | CL6: # | CM6: # | CN6: # | CO6: # | CP6: # | CQ6: # | CR6: # | CS6: # | CT6: # | CU6: # | CV6: # | CW6: # | CX6: # | CY6: # | CZ6: # | DA6: # | DB6: # | DC6: # | DD6: # | DE6: # | DF6: # | DG6: # | DH6: # | DI6: #
A7: a26_0 | B7: Chan, H.K., et al. | C7: prosp. cohort | D7: 44880 | E7: 44978 | F7: Malaysia | G7: AS; Manufacturing employees / household members in Kedah | H7: unclear | I7: 13900.839 | J7: unclear | K7: 2959 | L7: 1768 | M7: 396 | N7: =MAX(K7:M7) -> 2959 | O7: Number of people that collected / were sent self-tests | P7: # | Q7: # | R7: # | S7: # | T7: # | U7: # | V7: # | W7: 1017 | X7: 740 | Y7: 6 | Z7: Manufacturing employees | AA7: # | AB7: # | AC7: # | AD7: =IF(AND(AA7=0,AC7=0),1,0) -> 0 | AE7: # | AF7: # | AG7: unknown | AH7: # | AI7: # | AJ7: FlowFlex SARS-CoV-2 antigen rapid test | AK7: no | AL7: AN / MT | AM7: Workplace | AN7: Home | AO7: Unclear | AP7: # | AQ7: =ROUND(('Data extracted'!E7-'Data extracted'!D7)/7,0) -> 14 | AR7: # | AS7: # | AT7: # | AU7: no | AV7: no | AW7: Ag-RDT training at begin of the study; satisfaction surveys | AX7: # | AY7: # | AZ7: # | BA7: # | BB7: # | BC7: # | BD7: # | BE7: # | BF7: =SUM(BG7:BJ7) -> 0 | BG7: # | BH7: # | BI7: # | BJ7: # | BK7: =IFERROR(IF(BJ7<>"#",BJ7+BI7,"#"),"#") -> # | BL7: =SUM(BM7:BP7) -> 396 | BM7: 40 | BN7: 329 | BO7: 27 | BP7: # | BQ7: # | BR7: # | BS7: =SUM(BT7:BW7) -> 0 | BT7: # | BU7: # | BV7: # | BW7: # | BX7: =IFERROR(IF(BU7<>"#",BU7+BT7,"#"),"#") -> # | BY7: # | BZ7: # | CA7: # | CB7: Report result to employer; follow national COVID-19 guideline | CC7: # | CD7: # | CE7: # | CF7: # | CG7: # | CH7: # | CI7: # | CJ7: # | CK7: # | CL7: # | CM7: # | CN7: # | CO7: # | CP7: # | CQ7: # | CR7: # | CS7: # | CT7: # | CU7: # | CV7: # | CW7: # | CX7: # | CY7: More willing to self-isolate as much as possible | CZ7: Less worried about COVID-19 | DA7: # | DB7: # | DC7: # | DD7: # | DE7: # | DF7: # | DG7: # | DH7: # | DI7: #
A8: a27_1 | B8: Chen, S.H., et al. | C8: retrosp. cohort | D8: 44692 | E8: 44722 | F8: Taiwan | G8: AS; Patients of the National Taiwan University Children’s Hospital | H8: City | I8: 37826.616 | J8: regulated, country wide price | K8: 426 | L8: # | M8: # | N8: =MAX(K8:M8) -> 426 | O8: Number of people eligible for self-testing | P8: # | Q8: # | R8: 5 | S8: 2 | T8: 8 | U8: # | V8: # | W8: # | X8: 227 | Y8: # | Z8: General population | AA8: 389 | AB8: 37 | AC8: 0 | AD8: =IF(AND(AA8=0,AC8=0),1,0) -> 0 | AE8: 22 | AF8: 330 | AG8: unknown | AH8: 25 | AI8: # | AJ8: Unclear | AK8: # | AL8: unclear | AM8: Purchase at free market (pharmacy etc.) | AN8: Home | AO8: Single | AP8: # | AQ8: =ROUND(('Data extracted'!E8-'Data extracted'!D8)/7,0) -> 4 | AR8: # | AS8: # | AT8: # | AU8: no | AV8: no | AW8: unclear | AX8: STOPP self-testing since testing was only done once | AY8: # | AZ8: # | BA8: # | BB8: # | BC8: # | BD8: RT-PCR | BE8: NP | BF8: =SUM(BG8:BJ8) -> 249 | BG8: 186 | BH8: 38 | BI8: 24 | BJ8: 1 | BK8: =IFERROR(IF(BJ8<>"#",BJ8+BI8,"#"),"#") -> 25 | BL8: # | BM8: # | BN8: # | BO8: # | BP8: # | BQ8: RT-PCR | BR8: NP | BS8: =SUM(BT8:BW8) -> 249 | BT8: 186 | BU8: 38 | BV8: 24 | BW8: 1 | BX8: =IFERROR(IF(BU8<>"#",BU8+BT8,"#"),"#") -> 224 | BY8: C19ST or RT-PCR | BZ8: 30min | CA8: # | CB8: # | CC8: # | CD8: # | CE8: # | CF8: # | CG8: # | CH8: # | CI8: # | CJ8: # | CK8: # | CL8: # | CM8: # | CN8: # | CO8: # | CP8: # | CQ8: # | CR8: # | CS8: # | CT8: # | CU8: # | CV8: # | CW8: # | CX8: # | CY8: # | CZ8: # | DA8: # | DB8: # | DC8: # | DD8: # | DE8: # | DF8: # | DG8: # | DH8: # | DI8: #
A9: a27_2 | B9: Chen, S.H., et al. | C9: retrosp. cohort | D9: 44692 | E9: 44722 | F9: Taiwan | G9: AS; Patients of the National Taiwan University Children’s Hospital | H9: City | I9: 37826.616 | J9: regulated, country wide price | K9: 201 | L9: # | M9: # | N9: =MAX(K9:M9) -> 201 | O9: Number of people eligible for self-testing | P9: # | Q9: # | R9: 40 | S9: 36 | T9: 44 | U9: # | V9: # | W9: # | X9: 66 | Y9: # | Z9: General population | AA9: 154 | AB9: 48 | AC9: 0 | AD9: =IF(AND(AA9=0,AC9=0),1,0) -> 0 | AE9: 13 | AF9: 154 | AG9: unknown | AH9: 198 | AI9: # | AJ9: Unclear | AK9: # | AL9: unclear | AM9: Purchase at free market (pharmacy etc.) | AN9: Home | AO9: Single | AP9: # | AQ9: =ROUND(('Data extracted'!E9-'Data extracted'!D9)/7,0) -> 4 | AR9: # | AS9: # | AT9: # | AU9: no | AV9: no | AW9: unclear | AX9: STOPP self-testing since testing was only done once | AY9: # | AZ9: # | BA9: # | BB9: # | BC9: # | BD9: RT-PCR | BE9: NP | BF9: =SUM(BG9:BJ9) -> 148 | BG9: 78 | BH9: 29 | BI9: 36 | BJ9: 5 | BK9: =IFERROR(IF(BJ9<>"#",BJ9+BI9,"#"),"#") -> 41 | BL9: # | BM9: # | BN9: # | BO9: # | BP9: # | BQ9: RT-PCR | BR9: NP | BS9: =SUM(BT9:BW9) -> 148 | BT9: 78 | BU9: 29 | BV9: 36 | BW9: 5 | BX9: =IFERROR(IF(BU9<>"#",BU9+BT9,"#"),"#") -> 107 | BY9: C19ST or RT-PCR | BZ9: 30min | CA9: # | CB9: # | CC9: # | CD9: # | CE9: # | CF9: # | CG9: # | CH9: # | CI9: # | CJ9: # | CK9: # | CL9: # | CM9: # | CN9: # | CO9: # | CP9: # | CQ9: # | CR9: # | CS9: # | CT9: # | CU9: # | CV9: # | CW9: # | CX9: # | CY9: # | CZ9: # | DA9: # | DB9: # | DC9: # | DD9: # | DE9: # | DF9: # | DG9: # | DH9: # | DI9: #
A10: a28_1 | B10: Chong, S.J., et al. | C10: prosp. cohort | D10: 44567 | E10: 44609 | F10: Singapore | G10: AS; Adults across Singapore | H10: City | I10: 94480.797 | J10: unclear | K10: # | L10: # | M10: 342302 | N10: =MAX(K10:M10) -> 342302 | O10: Number of people that reported self-testing results | P10: # | Q10: # | R10: # | S10: # | T10: # | U10: # | V10: # | W10: # | X10: # | Y10: # | Z10: General population | AA10: # | AB10: # | AC10: # | AD10: =IF(AND(AA10=0,AC10=0),1,0) -> 0 | AE10: # | AF10: Close contact | AG10: unknown | AH10: # | AI10: # | AJ10: Unclear | AK10: # | AL10: # | AM10: Government | AN10: Home | AO10: Routine | AP10: 7 | AQ10: 1 | AR10: =AQ10*AP10*M10 -> 2396114 | AS10: # | AT10: # | AU10: no | AV10: no | AW10: # | AX10: # | AY10: # | AZ10: # | BA10: # | BB10: # | BC10: # | BD10: # | BE10: # | BF10: =SUM(BG10:BJ10) -> 0 | BG10: # | BH10: # | BI10: # | BJ10: # | BK10: =IFERROR(IF(BJ10<>"#",BJ10+BI10,"#"),"#") -> # | BL10: =SUM(BM10:BP10) -> 342302 | BM10: 37220 | BN10: 305082 | BO10: # | BP10: # | BQ10: RT-PCR | BR10: # | BS10: 8767 | BT10: # | BU10: # | BV10: # | BW10: # | BX10: =IFERROR(IF(BU10<>"#",BU10+BT10,"#"),"#") -> # | BY10: # | BZ10: # | CA10: # | CB10: Notify government authorities (visit specific website to understand exact steps) | CC10: # | CD10: Leave self-isolation and continue daily acitivities; re-test daily ; notify authorities if test was taken on last day of isolation period (day 7) | CE10: # | CF10: # | CG10: # | CH10: # | CI10: # | CJ10: # | CK10: # | CL10: # | CM10: # | CN10: # | CO10: # | CP10: # | CQ10: # | CR10: # | CS10: # | CT10: # | CU10: # | CV10: # | CW10: # | CX10: # | CY10: # | CZ10: # | DA10: # | DB10: # | DC10: # | DD10: # | DE10: # | DF10: # | DG10: # | DH10: # | DI10: #
A11: a28_2 | B11: Chong, S.J., et al. | C11: prosp. cohort | D11: 44567 | E11: 44609 | F11: Singapore | G11: AS; Adults across Singapore | H11: City | I11: 94480.797 | J11: unclear | K11: # | L11: # | M11: 297340 | N11: =MAX(K11:M11) -> 297340 | O11: Number of people that reported self-testing results | P11: # | Q11: # | R11: # | S11: # | T11: # | U11: # | V11: # | W11: # | X11: # | Y11: # | Z11: General population | AA11: # | AB11: # | AC11: # | AD11: =IF(AND(AA11=0,AC11=0),1,0) -> 0 | AE11: # | AF11: Close contact | AG11: unknown | AH11: # | AI11: # | AJ11: Unclear | AK11: # | AL11: # | AM11: Government | AN11: Home | AO11: Routine | AP11: 6 | AQ11: 1 | AR11: =AQ11*AP11*M11 -> 1784040 | AS11: # | AT11: # | AU11: no | AV11: no | AW11: # | AX11: # | AY11: # | AZ11: # | BA11: # | BB11: # | BC11: # | BD11: # | BE11: # | BF11: =SUM(BG11:BJ11) -> 0 | BG11: # | BH11: # | BI11: # | BJ11: # | BK11: =IFERROR(IF(BJ11<>"#",BJ11+BI11,"#"),"#") -> # | BL11: =SUM(BM11:BP11) -> 297340 | BM11: 11577 | BN11: 285763 | BO11: # | BP11: # | BQ11: RT-PCR | BR11: # | BS11: 4925 | BT11: # | BU11: # | BV11: # | BW11: # | BX11: =IFERROR(IF(BU11<>"#",BU11+BT11,"#"),"#") -> # | BY11: # | BZ11: # | CA11: # | CB11: Notify government authorities (visit specific website to understand exact steps) | CC11: # | CD11: Leave self-isolation and continue daily acitivities; re-test daily ; notify authorities if test was taken on last day of isolation period (day 7) | CE11: # | CF11: # | CG11: # | CH11: # | CI11: # | CJ11: # | CK11: # | CL11: # | CM11: # | CN11: # | CO11: # | CP11: # | CQ11: # | CR11: # | CS11: # | CT11: # | CU11: # | CV11: # | CW11: # | CX11: # | CY11: # | CZ11: # | DA11: # | DB11: # | DC11: # | DD11: # | DE11: # | DF11: # | DG11: # | DH11: # | DI11: #
A12: a28_3 | B12: Chong, S.J., et al. | C12: prosp. cohort | D12: 44567 | E12: 44609 | F12: Singapore | G12: AS; Adults across Singapore | H12: City | I12: 94480.797 | J12: unclear | K12: # | L12: # | M12: 73259 | N12: =MAX(K12:M12) -> 73259 | O12: Number of people that reported self-testing results | P12: # | Q12: # | R12: # | S12: # | T12: # | U12: # | V12: # | W12: # | X12: # | Y12: # | Z12: General population | AA12: # | AB12: # | AC12: # | AD12: =IF(AND(AA12=0,AC12=0),1,0) -> 0 | AE12: # | AF12: Close contact | AG12: unknown | AH12: # | AI12: # | AJ12: Unclear | AK12: # | AL12: # | AM12: Government | AN12: Home | AO12: Routine | AP12: 6 | AQ12: 1 | AR12: =AQ12*AP12*M12 -> 439554 | AS12: # | AT12: # | AU12: no | AV12: no | AW12: # | AX12: # | AY12: # | AZ12: # | BA12: # | BB12: # | BC12: # | BD12: # | BE12: # | BF12: =SUM(BG12:BJ12) -> 0 | BG12: # | BH12: # | BI12: # | BJ12: # | BK12: =IFERROR(IF(BJ12<>"#",BJ12+BI12,"#"),"#") -> # | BL12: =SUM(BM12:BP12) -> 73259 | BM12: 1369 | BN12: 71890 | BO12: # | BP12: # | BQ12: RT-PCR | BR12: # | BS12: 649 | BT12: # | BU12: # | BV12: # | BW12: # | BX12: =IFERROR(IF(BU12<>"#",BU12+BT12,"#"),"#") -> # | BY12: # | BZ12: # | CA12: # | CB12: Notify government authorities (visit specific website to understand exact steps) | CC12: # | CD12: Leave self-isolation and continue daily acitivities; re-test daily ; notify authorities if test was taken on last day of isolation period (day 7) | CE12: # | CF12: # | CG12: # | CH12: # | CI12: # | CJ12: # | CK12: # | CL12: # | CM12: # | CN12: # | CO12: # | CP12: # | CQ12: # | CR12: # | CS12: # | CT12: # | CU12: # | CV12: # | CW12: # | CX12: # | CY12: # | CZ12: # | DA12: # | DB12: # | DC12: # | DD12: # | DE12: # | DF12: # | DG12: # | DH12: # | DI12: #
A13: a28_4 | B13: Chong, S.J., et al. | C13: prosp. cohort | D13: 44567 | E13: 44609 | F13: Singapore | G13: AS; Adults across Singapore | H13: City | I13: 94480.797 | J13: unclear | K13: # | L13: # | M13: 564 | N13: =MAX(K13:M13) -> 564 | O13: Number of people that reported self-testing results | P13: # | Q13: # | R13: # | S13: # | T13: # | U13: # | V13: # | W13: # | X13: # | Y13: # | Z13: General population | AA13: # | AB13: # | AC13: # | AD13: =IF(AND(AA13=0,AC13=0),1,0) -> 0 | AE13: # | AF13: Close contact | AG13: unknown | AH13: # | AI13: # | AJ13: Unclear | AK13: # | AL13: # | AM13: Government | AN13: Home | AO13: Routine | AP13: 6 | AQ13: 1 | AR13: =AQ13*AP13*M13 -> 3384 | AS13: # | AT13: # | AU13: no | AV13: no | AW13: # | AX13: # | AY13: # | AZ13: # | BA13: # | BB13: # | BC13: # | BD13: # | BE13: # | BF13: =SUM(BG13:BJ13) -> 0 | BG13: # | BH13: # | BI13: # | BJ13: # | BK13: =IFERROR(IF(BJ13<>"#",BJ13+BI13,"#"),"#") -> # | BL13: =SUM(BM13:BP13) -> 564 | BM13: 15 | BN13: 549 | BO13: # | BP13: # | BQ13: RT-PCR | BR13: # | BS13: 1561 | BT13: # | BU13: # | BV13: # | BW13: # | BX13: =IFERROR(IF(BU13<>"#",BU13+BT13,"#"),"#") -> # | BY13: # | BZ13: # | CA13: # | CB13: Notify government authorities (visit specific website to understand exact steps) | CC13: # | CD13: Leave self-isolation and continue daily acitivities; re-test daily ; notify authorities if test was taken on last day of isolation period (day 7) | CE13: # | CF13: # | CG13: # | CH13: # | CI13: # | CJ13: # | CK13: # | CL13: # | CM13: # | CN13: # | CO13: # | CP13: # | CQ13: # | CR13: # | CS13: # | CT13: # | CU13: # | CV13: # | CW13: # | CX13: # | CY13: # | CZ13: # | DA13: # | DB13: # | DC13: # | DD13: # | DE13: # | DF13: # | DG13: # | DH13: # | DI13: #
A14: a29_0 | B14: D'Agostino, E.M., et al. | C14: prosp. cohort | D14: 44518 | E14: 44561 | F14: United States | G14: NA; Individuals across Merced County, California | H14: City; semi-dense | I14: 89598.86 | J14: free | K14: # | L14: # | M14: 2469 | N14: =MAX(K14:M14) -> 2469 | O14: n/a | P14: # | Q14: # | R14: # | S14: # | T14: # | U14: # | V14: # | W14: # | X14: # | Y14: # | Z14: General population | AA14: # | AB14: # | AC14: # | AD14: =IF(AND(AA14=0,AC14=0),1,0) -> 0 | AE14: # | AF14: 319 | AG14: unknown | AH14: 2058 | AI14: # | AJ14: QuickVue | AK14: no | AL14: AN / MT | AM14: Community workers | AN14: Home | AO14: Unclear | AP14: # | AQ14: # | AR14: # | AS14: 3262 | AT14: 2469 | AU14: no | AV14: no | AW14: # | AX14: # | AY14: =SUM(AZ14:BC14) -> 2469 | AZ14: 235 | BA14: 2234 | BB14: 0 | BC14: # | BD14: # | BE14: # | BF14: =SUM(BG14:BJ14) -> 0 | BG14: # | BH14: # | BI14: # | BJ14: # | BK14: =IFERROR(IF(BJ14<>"#",BJ14+BI14,"#"),"#") -> # | BL14: =SUM(BM14:BP14) -> 0 | BM14: # | BN14: # | BO14: # | BP14: # | BQ14: # | BR14: # | BS14: =SUM(BT14:BW14) -> 0 | BT14: # | BU14: # | BV14: # | BW14: # | BX14: =IFERROR(IF(BU14<>"#",BU14+BT14,"#"),"#") -> # | BY14: # | BZ14: # | CA14: # | CB14: # | CC14: # | CD14: # | CE14: # | CF14: # | CG14: # | CH14: # | CI14: # | CJ14: # | CK14: # | CL14: # | CM14: # | CN14: # | CO14: # | CP14: # | CQ14: # | CR14: # | CS14: # | CT14: # | CU14: # | CV14: # | CW14: # | CX14: # | CY14: # | CZ14: # | DA14: # | DB14: # | DC14: # | DD14: # | DE14: # | DF14: # | DG14: # | DH14: # | DI14: #
A15: a30_0 | B15: Downs, L.O., et al | C15: prosp. cohort | D15: 44158 | E15: 44205 | F15: United Kingdom | G15: UK; Oxford University Hospital | H15: City | I15: 56660.868 | J15: unclear | K15: # | L15: 8657 | M15: 7567 | N15: =MAX(K15:M15) -> 8657 | O15: Number of people that collected self-tests | P15: # | Q15: # | R15: # | S15: # | T15: # | U15: # | V15: # | W15: # | X15: # | Y15: # | Z15: Healthcare Professionals | AA15: 0 | AB15: 7567 | AC15: 0 | AD15: =IF(AND(AA15=0,AC15=0),1,0) -> 1 | AE15: # | AF15: unclear | AG15: unknown | AH15: # | AI15: # | AJ15: Innova LFD | AK15: no | AL15: AN / MT | AM15: Employer | AN15: Home | AO15: Routine | AP15: 2 | AQ15: =ROUND(('Data extracted'!E15-'Data extracted'!D15)/7,0) -> 7 | AR15: =AQ15*AP15*M15 -> 105938 | AS15: # | AT15: 46503 | AU15: no | AV15: no | AW15: RT-PCR screening of asymptomatic persons | AX15: # | AY15: =SUM(AZ15:BC15) -> 46503 | AZ15: 328 | BA15: 45710 | BB15: 465 | BC15: # | BD15: RT-PCR | BE15: NP / OP | BF15: =SUM(BG15:BJ15) -> 169 | BG15: 161 | BH15: # | BI15: # | BJ15: 8 | BK15: =IFERROR(IF(BJ15<>"#",BJ15+BI15,"#"),"#") -> # | BL15: =SUM(BM15:BP15) -> 295 | BM15: 295 | BN15: # | BO15: # | BP15: # | BQ15: # | BR15: # | BS15: =SUM(BT15:BW15) -> 0 | BT15: # | BU15: # | BV15: # | BW15: # | BX15: =IFERROR(IF(BU15<>"#",BU15+BT15,"#"),"#") -> # | BY15: # | BZ15: # | CA15: # | CB15: Some individuals received confirmatory testing, but unclear by which means it was determined whether individuals would receive confirmatory testing or not | CC15: unclear - some individuals received confirmatory testing, but unclear by which means it was determined whether individuals would receive confirmatory testing or not | CD15: # | CE15: # | CF15: # | CG15: # | CH15: # | CI15: # | CJ15: # | CK15: # | CL15: # | CM15: # | CN15: # | CO15: # | CP15: # | CQ15: # | CR15: # | CS15: # | CT15: # | CU15: # | CV15: # | CW15: # | CX15: # | CY15: # | CZ15: # | DA15: # | DB15: # | DC15: # | DD15: # | DE15: # | DF15: # | DG15: # | DH15: # | DI15: #
A16: a31_0 | B16: Du, Z., et al. | C16: retrospective | D16: 44618 | E16: 44646 | F16: Hong Kong | G16: AS; Individuals across Hong Kong | H16: City | I16: 56843.908 | J16: unclear | K16: # | L16: # | M16: # | N16: # | O16: n/a | P16: # | Q16: # | R16: # | S16: # | T16: # | U16: # | V16: # | W16: # | X16: # | Y16: # | Z16: General population | AA16: # | AB16: # | AC16: # | AD16: =IF(AND(AA16=0,AC16=0),1,0) -> 0 | AE16: # | AF16: # | AG16: unknown | AH16: # | AI16: # | AJ16: Unclear | AK16: # | AL16: # | AM16: # | AN16: Unclear | AO16: Unclear | AP16: # | AQ16: # | AR16: # | AS16: # | AT16: # | AU16: # | AV16: # | AW16: RT-PCR testing and COVID-19 Stringency Index | AX16: # | AY16: # | AZ16: # | BA16: # | BB16: # | BC16: # | BD16: # | BE16: # | BF16: =SUM(BG16:BJ16) -> 0 | BG16: # | BH16: # | BI16: # | BJ16: # | BK16: =IFERROR(IF(BJ16<>"#",BJ16+BI16,"#"),"#") -> # | BL16: =SUM(BM16:BP16) -> 0 | BM16: # | BN16: # | BO16: # | BP16: # | BQ16: # | BR16: # | BS16: =SUM(BT16:BW16) -> 0 | BT16: # | BU16: # | BV16: # | BW16: # | BX16: =IFERROR(IF(BU16<>"#",BU16+BT16,"#"),"#") -> # | BY16: C19ST | BZ16: 30min | CA16: # | CB16: # | CC16: # | CD16: # | CE16: # | CF16: # | CG16: # | CH16: # | CI16: # | CJ16: # | CK16: # | CL16: # | CM16: # | CN16: # | CO16: # | CP16: # | CQ16: # | CR16: # | CS16: ="lower case fatality ratio (CFR), which declined substantially from 0.005 on 25 February to 0.003 on 26 February 2022, when the programme of RAT testing was initiated in Hong Kong on 26 February 2022" -> lower case fatality ratio (CFR), which declined substantially from 0.005 on 25 February to 0.003 on 26 February 2022, when the programme of RAT testing was initiated in Hong Kong on 26 February 2022 | CT16: # | CU16: # | CV16: # | CW16: # | CX16: # | CY16: # | CZ16: # | DA16: # | DB16: # | DC16: # | DD16: # | DE16: # | DF16: # | DG16: # | DH16: # | DI16: #
A17: a32_1 | B17: Engels, G., et al. | C17: prosp. cohort | D17: 44319 | E17: 44400 | F17: Germany | G17: EU; Daycare centers in Wuerzburg, Bavaria | H17: City | I17: 59925.317 | J17: unclear | K17: 836 | L17: 280 | M17: 280 | N17: =MAX(K17:M17) -> 836 | O17: Number of people that reported self-testing results | P17: # | Q17: # | R17: # | S17: # | T17: # | U17: # | V17: # | W17: =94+31 -> 125 | X17: =121+34 -> 155 | Y17: # | Z17: K-12 students and staff | AA17: 0 | AB17: 280 | AC17: 0 | AD17: =IF(AND(AA17=0,AC17=0),1,0) -> 1 | AE17: 37 | AF17: # | AG17: unknown | AH17: # | AI17: 5 | AJ17: AST | AK17: no | AL17: AN / MT | AM17: unclear | AN17: Home | AO17: Routine | AP17: 2 | AQ17: =ROUND(('Data extracted'!E17-'Data extracted'!D17)/7,0) -> 12 | AR17: =AQ17*AP17*M17 -> 6720 | AS17: # | AT17: 2896 | AU17: yes | AV17: no | AW17: saliva (self-sampled) pooled RT-PCR testing | AX17: ANTIBODY testing at the beginning and end of study period | AY17: =SUM(AZ17:BC17) -> 2896 | AZ17: 0 | BA17: 2896 | BB17: 0 | BC17: 0 | BD17: RT-PCR | BE17: # | BF17: =SUM(BG17:BJ17) -> 0 | BG17: # | BH17: # | BI17: # | BJ17: # | BK17: =IFERROR(IF(BJ17<>"#",BJ17+BI17,"#"),"#") -> # | BL17: =SUM(BM17:BP17) -> 280 | BM17: 0 | BN17: 280 | BO17: # | BP17: # | BQ17: Antibodies | BR17: # | BS17: =SUM(BT17:BW17) -> 0 | BT17: # | BU17: 0 | BV17: # | BW17: # | BX17: =IFERROR(IF(BU17<>"#",BU17+BT17,"#"),"#") -> # | BY17: # | BZ17: # | CA17: # | CB17: # | CC17: # | CD17: # | CE17: # | CF17: # | CG17: # | CH17: testing was perceived as uncomfortable by some; testing discomfort causing interactive problems parents-kids | CI17: # | CJ17: # | CK17: # | CL17: # | CM17: # | CN17: # | CO17: # | CP17: # | CQ17: # | CR17: # | CS17: # | CT17: # | CU17: # | CV17: # | CW17: # | CX17: # | CY17: # | CZ17: Insecurity in regards to test accuracy and performing the test correctly; some children were interested in testing, others refused having test performed; felt that C19ST increased sense of safety because of reduced TAT | DA17: # | DB17: # | DC17: # | DD17: Positive acknowledgement of little time required to perform tests | DE17: # | DF17: # | DG17: # | DH17: # | DI17: #
A18: a32_2 | B18: Engels, G., et al. | C18: prosp. cohort | D18: 44319 | E18: 44400 | F18: Germany | G18: EU; Daycare centers in Wuerzburg, Bavaria | H18: City | I18: 59925.317 | J18: unclear | K18: 190 | L18: 110 | M18: 110 | N18: =MAX(K18:M18) -> 190 | O18: Number of people that reported self-testing results | P18: # | Q18: # | R18: # | S18: # | T18: # | U18: # | V18: # | W18: =74+10 -> 84 | X18: =4+2 -> 6 | Y18: # | Z18: K-12 students and staff | AA18: 0 | AB18: 110 | AC18: 0 | AD18: =IF(AND(AA18=0,AC18=0),1,0) -> 1 | AE18: 20 | AF18: # | AG18: unknown | AH18: # | AI18: 3 | AJ18: AST | AK18: no | AL18: AN / MT | AM18: unclear | AN18: Home | AO18: Routine | AP18: 2 | AQ18: =ROUND(('Data extracted'!E18-'Data extracted'!D18)/7,0) -> 12 | AR18: =AQ18*AP18*M18 -> 2640 | AS18: # | AT18: 1022 | AU18: no | AV18: no | AW18: saliva (self-sampled) pooled RT-PCR testing | AX18: # | AY18: =SUM(AZ18:BC18) -> 1022 | AZ18: 0 | BA18: 1022 | BB18: 0 | BC18: 0 | BD18: RT-PCR | BE18: # | BF18: =SUM(BG18:BJ18) -> 0 | BG18: # | BH18: # | BI18: # | BJ18: # | BK18: =IFERROR(IF(BJ18<>"#",BJ18+BI18,"#"),"#") -> # | BL18: =SUM(BM18:BP18) -> 110 | BM18: 0 | BN18: 110 | BO18: # | BP18: # | BQ18: RT-PCR | BR18: # | BS18: =SUM(BT18:BW18) -> 0 | BT18: # | BU18: # | BV18: # | BW18: # | BX18: =IFERROR(IF(BU18<>"#",BU18+BT18,"#"),"#") -> # | BY18: # | BZ18: # | CA18: # | CB18: # | CC18: # | CD18: # | CE18: # | CF18: # | CG18: # | CH18: testing was perceived as uncomfortable by some; testing discomfort causing interactive problems parents-kids | CI18: # | CJ18: # | CK18: # | CL18: # | CM18: # | CN18: # | CO18: # | CP18: # | CQ18: # | CR18: # | CS18: # | CT18: # | CU18: # | CV18: # | CW18: # | CX18: # | CY18: # | CZ18: Insecurity in regards to test accuracy and performing the test correctly; some children were interested in testing, others refused having test performed; felt that C19ST increased sense of safety because of reduced TAT | DA18: # | DB18: # | DC18: # | DD18: Positive acknowledgement of little time required to perform tests | DE18: # | DF18: # | DG18: # | DH18: # | DI18: #
A19: a33_0 | B19: Gorgels, K.M.F., et al. | C19: retrosp. cohort | D19: 44319 | E19: 44661 | F19: Netherlands | G19: EU; All public health services facilities in the Netherlands | H19: unclear | I19: 73173.715 | J19: unclear | K19: # | L19: # | M19: # | N19: 3599894 | O19: Number of people that reported self-testing results | P19: # | Q19: # | R19: # | S19: # | T19: # | U19: # | V19: # | W19: 1863909 | X19: 1734482 | Y19: 1503 | Z19: General population | AA19: 3195409 | AB19: 404485 | AC19: 0 | AD19: =IF(AND(AA19=0,AC19=0),1,0) -> 0 | AE19: # | AF19: # | AG19: unknown | AH19: Booster: 957,443; Fully vaccinated: 888,199; Partly vaccinated: 153,579; Unvaccinated: 1,057,391; Unknown: 543,282 | AI19: # | AJ19: Unclear | AK19: # | AL19: # | AM19: # | AN19: Unclear | AO19: Unclear | AP19: # | AQ19: # | AR19: # | AS19: # | AT19: # | AU19: no | AV19: no | AW19: # | AX19: # | AY19: # | AZ19: # | BA19: # | BB19: # | BC19: # | BD19: # | BE19: # | BF19: =SUM(BG19:BJ19) -> 0 | BG19: # | BH19: # | BI19: # | BJ19: # | BK19: =IFERROR(IF(BJ19<>"#",BJ19+BI19,"#"),"#") -> # | BL19: =SUM(BM19:BP19) -> 3599894 | BM19: 3599894 | BN19: # | BO19: # | BP19: # | BQ19: RT-PCR | BR19: # | BS19: =SUM(BT19:BW19) -> 3599894 | BT19: 3291877 | BU19: # | BV19: # | BW19: 308017 | BX19: =IFERROR(IF(BU19<>"#",BU19+BT19,"#"),"#") -> # | BY19: RT-PCR | BZ19: # | CA19: # | CB19: Follow national COVID-19 guideline, i.e., perform an RT-PCR for confirmatory testing | CC19: compulsory (by goverment guidance) | CD19: # | CE19: # | CF19: # | CG19: # | CH19: # | CI19: # | CJ19: # | CK19: # | CL19: # | CM19: # | CN19: # | CO19: # | CP19: # | CQ19: # | CR19: # | CS19: # | CT19: # | CU19: # | CV19: # | CW19: # | CX19: # | CY19: Unnecessary social isolation if false-positive | CZ19: Unnecessary social isolation if false-positive | DA19: # | DB19: # | DC19: # | DD19: # | DE19: # | DF19: # | DG19: # | DH19: # | DI19: #
A20: a34_0 | B20: Harmon, A., et al. | C20: prosp. cohort | D20: # | E20: # | F20: United States | G20: NA; Affiliates of co-working laboratories in Boston + Cambridge, MA | H20: City | I20: 89598.86 | J20: unclear | K20: # | L20: # | M20: 257 | N20: =MAX(K20:M20) -> 257 | O20: Number of people that reported self-testing results | P20: # | Q20: # | R20: 35 | S20: # | T20: # | U20: 21 | V20: 72 | W20: 120 | X20: # | Y20: 137 | Z20: General population | AA20: # | AB20: # | AC20: # | AD20: =IF(AND(AA20=0,AC20=0),1,0) -> 0 | AE20: # | AF20: # | AG20: unknown | AH20: # | AI20: # | AJ20: E25Bio | AK20: # | AL20: AN / MT | AM20: Study | AN20: Home | AO20: Routine | AP20: 2 | AQ20: # | AR20: # | AS20: # | AT20: 2951 | AU20: no | AV20: no | AW20: RT-PCR for every specimen | AX20: CONTINUE | AY20: =SUM(AZ20:BA20) -> 2951 | AZ20: 144 | BA20: 2807 | BB20: # | BC20: # | BD20: RT-PCR | BE20: AN / MT | BF20: =SUM(BG20:BJ20) -> 2951 | BG20: 60 | BH20: 16 | BI20: 2791 | BJ20: 84 | BK20: =IFERROR(IF(BJ20<>"#",BJ20+BI20,"#"),"#") -> 2875 | BL20: 257 | BM20: 15 | BN20: 242 | BO20: # | BP20: # | BQ20: RT-PCR | BR20: AN / MT | BS20: =SUM(BT20:BW20) -> 257 | BT20: 15 | BU20: 0 | BV20: 242 | BW20: 0 | BX20: =IFERROR(IF(BU20<>"#",BU20+BT20,"#"),"#") -> 15 | BY20: RT-PCR | BZ20: # | CA20: 30 min. | CB20: Confirm result through RT-PCR or professional Ag-RDT; do not go to school | CC20: compulsory (by study design) | CD20: Continue work and routine testing | CE20: # | CF20: # | CG20: # | CH20: # | CI20: # | CJ20: # | CK20: # | CL20: # | CM20: # | CN20: # | CO20: # | CP20: # | CQ20: # | CR20: # | CS20: # | CT20: # | CU20: # | CV20: # | CW20: # | CX20: allowed work activities to continue safely | CY20: # | CZ20: # | DA20: # | DB20: # | DC20: # | DD20: # | DE20: include | DF20: include | DG20: # | DH20: # | DI20: #
A21: a35_1 | B21: Herbert, C., et al. (a) | C21: prosp. cohort | D21: 44423 | E21: 44607 | F21: United States | G21: NA; Individuals across Michigan (1st part of study) and the entire US (2nd part) | H21: unclear | I21: 89598.86 | J21: unclear | K21: # | L21: 1083 | M21: 1016 | N21: =MAX(K21:M21) -> 1083 | O21: Number of people eligible for self-testing | P21: # | Q21: # | R21: # | S21: # | T21: # | U21: # | V21: # | W21: # | X21: # | Y21: # | Z21: General population | AA21: 102 | AB21: 981 | AC21: 0 | AD21: =IF(AND(AA21=0,AC21=0),1,0) -> 0 | AE21: # | AF21: 262 people had close contact with a SARS-CoV-2 case | AG21: unknown | AH21: # | AI21: # | AJ21: QuickVue | AK21: no | AL21: AN / MT | AM21: Study | AN21: Home | AO21: Routine | AP21: 2 | AQ21: 12 | AR21: =AQ21*AP21*622 -> 14928 | AS21: # | AT21: 6580 | AU21: no | AV21: no | AW21: Weekly surveillance questionnaire, RT-PCR in case of two ro more sympoms or exposure | AX21: CONTINUE | AY21: # | AZ21: # | BA21: # | BB21: # | BC21: # | BD21: # | BE21: # | BF21: =SUM(BG21:BJ21) -> 0 | BG21: # | BH21: # | BI21: # | BJ21: # | BK21: =IFERROR(IF(BJ21<>"#",BJ21+BI21,"#"),"#") -> # | BL21: =SUM(BM21:BP21) -> 76 | BM21: =ROUND(1016*0.075,0) -> 76 | BN21: # | BO21: # | BP21: # | BQ21: # | BR21: # | BS21: =SUM(BT21:BW21) -> 0 | BT21: # | BU21: # | BV21: # | BW21: # | BX21: =IFERROR(IF(BU21<>"#",BU21+BT21,"#"),"#") -> # | BY21: # | BZ21: # | CA21: 10 min. | CB21: Upload image of test strip; repeat antigen test on the same day or after 1 day; perform confirmatory test using at-home RT-PCR collection kit; care directed by participant's primary or urgent care provider | CC21: compulsory (by study design) | CD21: continue to test twice-weekly until end of 12-week period | CE21: # | CF21: # | CG21: # | CH21: # | CI21: # | CJ21: # | CK21: # | CL21: # | CM21: # | CN21: # | CO21: # | CP21: # | CQ21: # | CR21: # | CS21: # | CT21: # | CU21: # | CV21: # | CW21: # | CX21: # | CY21: # | CZ21: # | DA21: # | DB21: # | DC21: # | DD21: # | DE21: # | DF21: # | DG21: # | DH21: # | DI21: #
A22: a35_2 | B22: Herbert, C., et al. (a) | C22: prosp. cohort | D22: 44423 | E22: 44607 | F22: United States | G22: NA; Individuals across Michigan (1st part of study) and the entire US (2nd part) | H22: unclear | I22: 89598.86 | J22: unclear | K22: # | L22: # | M22: 801 | N22: =MAX(K22:M22) -> 801 | O22: Number of people eligible for self-testing | P22: # | Q22: # | R22: # | S22: # | T22: # | U22: # | V22: # | W22: # | X22: # | Y22: # | Z22: General population | AA22: # | AB22: # | AC22: # | AD22: =IF(AND(AA22=0,AC22=0),1,0) -> 0 | AE22: # | AF22: # | AG22: unknown | AH22: # | AI22: # | AJ22: QuickVue | AK22: no | AL22: AN / MT | AM22: Study | AN22: Home | AO22: Routine | AP22: 2 | AQ22: 2 | AR22: # | AS22: # | AT22: # | AU22: no | AV22: no | AW22: Weekly surveillance questionnaire | AX22: # | AY22: # | AZ22: # | BA22: # | BB22: # | BC22: # | BD22: # | BE22: # | BF22: =SUM(BG22:BJ22) -> 0 | BG22: # | BH22: # | BI22: # | BJ22: # | BK22: =IFERROR(IF(BJ22<>"#",BJ22+BI22,"#"),"#") -> # | BL22: =SUM(BM22:BP22) -> 0 | BM22: # | BN22: # | BO22: # | BP22: # | BQ22: # | BR22: # | BS22: =SUM(BT22:BW22) -> 0 | BT22: # | BU22: # | BV22: # | BW22: # | BX22: =IFERROR(IF(BU22<>"#",BU22+BT22,"#"),"#") -> # | BY22: # | BZ22: # | CA22: 10 min. | CB22: Upload image of test strip; repeat antigen test on the same day or after 1 day; perform confirmatory test using at-home RT-PCR collection kit; care directed by participant's primary or urgent care provider | CC22: compulsory (by study design) | CD22: continue to test twice-weekly until end of 2-week period, then continue weekly symptom survey | CE22: # | CF22: # | CG22: # | CH22: # | CI22: # | CJ22: # | CK22: # | CL22: # | CM22: # | CN22: # | CO22: # | CP22: # | CQ22: # | CR22: # | CS22: # | CT22: # | CU22: # | CV22: # | CW22: # | CX22: # | CY22: # | CZ22: # | DA22: # | DB22: # | DC22: # | DD22: # | DE22: # | DF22: # | DG22: # | DH22: # | DI22: #
